ðŸ“‚ EÄŸitim verisi yÃ¼kleniyor...
Traceback (most recent call last):
  File "/Users/yusufegeeren/Desktop/COINSPACE/Coinspace_bot/utils/train_utils.py", line 160, in <module>
    run_training()
  File "/Users/yusufegeeren/Desktop/COINSPACE/Coinspace_bot/utils/train_utils.py", line 35, in run_training
    df = pd.read_csv(csv_path)
         ^^^^^^^^^^^^^^^^^^^^^
  File "/Users/yusufegeeren/Coinspace_bot/venv/lib/python3.11/site-packages/pandas/io/parsers/readers.py", line 1026, in read_csv
    return _read(filepath_or_buffer, kwds)
           ^^^^^^^^^^^^^^^^^^^^^^^^^^^^^^^
  File "/Users/yusufegeeren/Coinspace_bot/venv/lib/python3.11/site-packages/pandas/io/parsers/readers.py", line 620, in _read
    parser = TextFileReader(filepath_or_buffer, **kwds)
             ^^^^^^^^^^^^^^^^^^^^^^^^^^^^^^^^^^^^^^^^^^
  File "/Users/yusufegeeren/Coinspace_bot/venv/lib/python3.11/site-packages/pandas/io/parsers/readers.py", line 1620, in __init__
    self._engine = self._make_engine(f, self.engine)
                   ^^^^^^^^^^^^^^^^^^^^^^^^^^^^^^^^^
  File "/Users/yusufegeeren/Coinspace_bot/venv/lib/python3.11/site-packages/pandas/io/parsers/readers.py", line 1880, in _make_engine
    self.handles = get_handle(
                   ^^^^^^^^^^^
  File "/Users/yusufegeeren/Coinspace_bot/venv/lib/python3.11/site-packages/pandas/io/common.py", line 873, in get_handle
    handle = open(
             ^^^^^
FileNotFoundError: [Errno 2] No such file or directory: 'training_data.csv'
